
[2025-06-21 03:49:29.401966] ERROR on input: hey do you remember the last session
Traceback (most recent call last):
  File "C:\MOTHER\mother_ai\gui\main_window.py", line 97, in handle_input
    prompt = build_prompt_with_context(user_input, self.config)
             ^^^^^^^^^^^^^^^^^^^^^^^^^^^^^^^^^^^^^^^^^^^^^^^^^^
  File "C:\MOTHER\mother_ai\processing\context_builder.py", line 22, in build_prompt_with_context
    facts = all_facts()
            ^^^^^^^^^^^
  File "C:\MOTHER\mother_ai\memory\structured_store.py", line 35, in all_facts
    c.execute('SELECT key, value FROM facts')
sqlite3.OperationalError: no such table: facts


[2025-06-21 03:49:33.555870] ERROR on input: hey
Traceback (most recent call last):
  File "C:\MOTHER\mother_ai\gui\main_window.py", line 97, in handle_input
    prompt = build_prompt_with_context(user_input, self.config)
             ^^^^^^^^^^^^^^^^^^^^^^^^^^^^^^^^^^^^^^^^^^^^^^^^^^
  File "C:\MOTHER\mother_ai\processing\context_builder.py", line 22, in build_prompt_with_context
    facts = all_facts()
            ^^^^^^^^^^^
  File "C:\MOTHER\mother_ai\memory\structured_store.py", line 35, in all_facts
    c.execute('SELECT key, value FROM facts')
sqlite3.OperationalError: no such table: facts


[2025-06-21 03:51:34.681821] ERROR on input: hey
Traceback (most recent call last):
  File "C:\MOTHER\mother_ai\gui\main_window.py", line 97, in handle_input
    prompt = build_prompt_with_context(user_input, self.config)
             ^^^^^^^^^^^^^^^^^^^^^^^^^^^^^^^^^^^^^^^^^^^^^^^^^^
  File "C:\MOTHER\mother_ai\processing\context_builder.py", line 22, in build_prompt_with_context
    facts = all_facts()
            ^^^^^^^^^^^
  File "C:\MOTHER\mother_ai\memory\structured_store.py", line 35, in all_facts
    c.execute('SELECT key, value FROM facts')
sqlite3.OperationalError: no such table: facts

[2025-06-24 17:04:57.306000] Error in add_memory: AttributeError - 'Client' object has no attribute 'persist'

[ERROR] LLM request failed
Traceback (most recent call last):
  File "c:\MOTHER\.venv\Lib\site-packages\urllib3\connectionpool.py", line 534, in _make_request
    response = conn.getresponse()
               ^^^^^^^^^^^^^^^^^^
  File "c:\MOTHER\.venv\Lib\site-packages\urllib3\connection.py", line 565, in getresponse
    httplib_response = super().getresponse()
                       ^^^^^^^^^^^^^^^^^^^^^
  File "C:\Users\USER\AppData\Local\Programs\Python\Python312\Lib\http\client.py", line 1419, in getresponse
    response.begin()
  File "C:\Users\USER\AppData\Local\Programs\Python\Python312\Lib\http\client.py", line 331, in begin
    version, status, reason = self._read_status()
                              ^^^^^^^^^^^^^^^^^^^
  File "C:\Users\USER\AppData\Local\Programs\Python\Python312\Lib\http\client.py", line 292, in _read_status
    line = str(self.fp.readline(_MAXLINE + 1), "iso-8859-1")
               ^^^^^^^^^^^^^^^^^^^^^^^^^^^^^^
  File "C:\Users\USER\AppData\Local\Programs\Python\Python312\Lib\socket.py", line 707, in readinto
    return self._sock.recv_into(b)
           ^^^^^^^^^^^^^^^^^^^^^^^
TimeoutError: timed out

The above exception was the direct cause of the following exception:

Traceback (most recent call last):
  File "c:\MOTHER\.venv\Lib\site-packages\requests\adapters.py", line 667, in send
    resp = conn.urlopen(
           ^^^^^^^^^^^^^
  File "c:\MOTHER\.venv\Lib\site-packages\urllib3\connectionpool.py", line 841, in urlopen
    retries = retries.increment(
              ^^^^^^^^^^^^^^^^^^
  File "c:\MOTHER\.venv\Lib\site-packages\urllib3\util\retry.py", line 474, in increment
    raise reraise(type(error), error, _stacktrace)
          ^^^^^^^^^^^^^^^^^^^^^^^^^^^^^^^^^^^^^^^^
  File "c:\MOTHER\.venv\Lib\site-packages\urllib3\util\util.py", line 39, in reraise
    raise value
  File "c:\MOTHER\.venv\Lib\site-packages\urllib3\connectionpool.py", line 787, in urlopen
    response = self._make_request(
               ^^^^^^^^^^^^^^^^^^^
  File "c:\MOTHER\.venv\Lib\site-packages\urllib3\connectionpool.py", line 536, in _make_request
    self._raise_timeout(err=e, url=url, timeout_value=read_timeout)
  File "c:\MOTHER\.venv\Lib\site-packages\urllib3\connectionpool.py", line 367, in _raise_timeout
    raise ReadTimeoutError(
urllib3.exceptions.ReadTimeoutError: HTTPConnectionPool(host='localhost', port=11434): Read timed out. (read timeout=60)

During handling of the above exception, another exception occurred:

Traceback (most recent call last):
  File "C:\MOTHER\mother_ai\processing\llm_handler.py", line 17, in get_response
    res = requests.post("http://localhost:11434/api/chat", json={
          ^^^^^^^^^^^^^^^^^^^^^^^^^^^^^^^^^^^^^^^^^^^^^^^^^^^^^^^
  File "c:\MOTHER\.venv\Lib\site-packages\requests\api.py", line 115, in post
    return request("post", url, data=data, json=json, **kwargs)
           ^^^^^^^^^^^^^^^^^^^^^^^^^^^^^^^^^^^^^^^^^^^^^^^^^^^^
  File "c:\MOTHER\.venv\Lib\site-packages\requests\api.py", line 59, in request
    return session.request(method=method, url=url, **kwargs)
           ^^^^^^^^^^^^^^^^^^^^^^^^^^^^^^^^^^^^^^^^^^^^^^^^^
  File "c:\MOTHER\.venv\Lib\site-packages\requests\sessions.py", line 589, in request
    resp = self.send(prep, **send_kwargs)
           ^^^^^^^^^^^^^^^^^^^^^^^^^^^^^^
  File "c:\MOTHER\.venv\Lib\site-packages\requests\sessions.py", line 703, in send
    r = adapter.send(request, **kwargs)
        ^^^^^^^^^^^^^^^^^^^^^^^^^^^^^^^
  File "c:\MOTHER\.venv\Lib\site-packages\requests\adapters.py", line 713, in send
    raise ReadTimeout(e, request=request)
requests.exceptions.ReadTimeout: HTTPConnectionPool(host='localhost', port=11434): Read timed out. (read timeout=60)
[2025-06-25 21:29:33.248390] Error in add_memory: AttributeError - 'Client' object has no attribute 'persist'
[2025-06-25 21:31:03.133095] Error in add_memory: AttributeError - 'Client' object has no attribute 'persist'
[2025-06-25 21:33:05.826437] Error in add_memory: AttributeError - 'Client' object has no attribute 'persist'

[ERROR] LLM request failed
Traceback (most recent call last):
  File "c:\MOTHER\.venv\Lib\site-packages\urllib3\connectionpool.py", line 534, in _make_request
    response = conn.getresponse()
               ^^^^^^^^^^^^^^^^^^
  File "c:\MOTHER\.venv\Lib\site-packages\urllib3\connection.py", line 565, in getresponse
    httplib_response = super().getresponse()
                       ^^^^^^^^^^^^^^^^^^^^^
  File "C:\Users\USER\AppData\Local\Programs\Python\Python312\Lib\http\client.py", line 1419, in getresponse
    response.begin()
  File "C:\Users\USER\AppData\Local\Programs\Python\Python312\Lib\http\client.py", line 331, in begin
    version, status, reason = self._read_status()
                              ^^^^^^^^^^^^^^^^^^^
  File "C:\Users\USER\AppData\Local\Programs\Python\Python312\Lib\http\client.py", line 292, in _read_status
    line = str(self.fp.readline(_MAXLINE + 1), "iso-8859-1")
               ^^^^^^^^^^^^^^^^^^^^^^^^^^^^^^
  File "C:\Users\USER\AppData\Local\Programs\Python\Python312\Lib\socket.py", line 707, in readinto
    return self._sock.recv_into(b)
           ^^^^^^^^^^^^^^^^^^^^^^^
TimeoutError: timed out

The above exception was the direct cause of the following exception:

Traceback (most recent call last):
  File "c:\MOTHER\.venv\Lib\site-packages\requests\adapters.py", line 667, in send
    resp = conn.urlopen(
           ^^^^^^^^^^^^^
  File "c:\MOTHER\.venv\Lib\site-packages\urllib3\connectionpool.py", line 841, in urlopen
    retries = retries.increment(
              ^^^^^^^^^^^^^^^^^^
  File "c:\MOTHER\.venv\Lib\site-packages\urllib3\util\retry.py", line 474, in increment
    raise reraise(type(error), error, _stacktrace)
          ^^^^^^^^^^^^^^^^^^^^^^^^^^^^^^^^^^^^^^^^
  File "c:\MOTHER\.venv\Lib\site-packages\urllib3\util\util.py", line 39, in reraise
    raise value
  File "c:\MOTHER\.venv\Lib\site-packages\urllib3\connectionpool.py", line 787, in urlopen
    response = self._make_request(
               ^^^^^^^^^^^^^^^^^^^
  File "c:\MOTHER\.venv\Lib\site-packages\urllib3\connectionpool.py", line 536, in _make_request
    self._raise_timeout(err=e, url=url, timeout_value=read_timeout)
  File "c:\MOTHER\.venv\Lib\site-packages\urllib3\connectionpool.py", line 367, in _raise_timeout
    raise ReadTimeoutError(
urllib3.exceptions.ReadTimeoutError: HTTPConnectionPool(host='localhost', port=11434): Read timed out. (read timeout=60)

During handling of the above exception, another exception occurred:

Traceback (most recent call last):
  File "C:\MOTHER\mother_ai\processing\llm_handler.py", line 17, in get_response
    res = requests.post("http://localhost:11434/api/chat", json={
          ^^^^^^^^^^^^^^^^^^^^^^^^^^^^^^^^^^^^^^^^^^^^^^^^^^^^^^^
  File "c:\MOTHER\.venv\Lib\site-packages\requests\api.py", line 115, in post
    return request("post", url, data=data, json=json, **kwargs)
           ^^^^^^^^^^^^^^^^^^^^^^^^^^^^^^^^^^^^^^^^^^^^^^^^^^^^
  File "c:\MOTHER\.venv\Lib\site-packages\requests\api.py", line 59, in request
    return session.request(method=method, url=url, **kwargs)
           ^^^^^^^^^^^^^^^^^^^^^^^^^^^^^^^^^^^^^^^^^^^^^^^^^
  File "c:\MOTHER\.venv\Lib\site-packages\requests\sessions.py", line 589, in request
    resp = self.send(prep, **send_kwargs)
           ^^^^^^^^^^^^^^^^^^^^^^^^^^^^^^
  File "c:\MOTHER\.venv\Lib\site-packages\requests\sessions.py", line 703, in send
    r = adapter.send(request, **kwargs)
        ^^^^^^^^^^^^^^^^^^^^^^^^^^^^^^^
  File "c:\MOTHER\.venv\Lib\site-packages\requests\adapters.py", line 713, in send
    raise ReadTimeout(e, request=request)
requests.exceptions.ReadTimeout: HTTPConnectionPool(host='localhost', port=11434): Read timed out. (read timeout=60)
[2025-06-25 21:35:03.344140] Error in add_memory: AttributeError - 'Client' object has no attribute 'persist'
[2025-06-25 21:47:20.365420] Error in add_memory: AttributeError - 'Client' object has no attribute 'persist'
[2025-06-25 21:49:09.760937] Error in add_memory: AttributeError - 'Client' object has no attribute 'persist'
